Workbook

Sheet Raw_Data
A1: Wallet Account Statement | E1: Date Printed | F1: 27 Dec 2025 22:27:55
A2: Account Name | B2: MUHAMMAD ABUBAKAR UMAR | C2: Account Number | D2: 8147735015 | E2: Address | F2: Danbare quarters, Opposite Buk gate, Ungogo, Ungogo, Kano
A3: Account Type | B3: Wallet Account | C3: Period | D3: 01 Jan 2025-26 Dec 2025
A4: Opening Balance | B4: ₦1,587.02 | C4: Total Debit | D4: ₦5,924,353.47 | E4: Debit Count | F4: 1505
A5: Closing Balance | B5: ₦6,318.86 | C5: Total Credit | D5: ₦5,929,085.31 | E5: Credit Count | F5: 377
A7: Trans. Date | B7: Value Date | C7: Description | D7: Debit(₦) | E7: Credit(₦) | F7: Balance After(₦) | G7: Channel | H7: Transaction Reference
A8: 01 Jan 2025 04:07:19 | B8: 01 Jan 2025 | C8: Airtime | 8147735015 | MTN | D8: 200.00 | E8: -- | F8: 1,387.02 | G8: Mobile | H8: 250101100100630513708890
A9: 01 Jan 2025 13:29:19 | B9: 01 Jan 2025 | C9: Transfer from KHAIRAT ZUBAIRU | OPay | 703****966 | D9: -- | E9: 300.00 | F9: 1,687.02 | G9: Mobile | H9: 250101010100635414096083
A10: 01 Jan 2025 14:00:41 | B10: 01 Jan 2025 | C10: Transfer to POS Transfer-AMINA HARUNA | MONIE POINT | 5730253158 | D10: 700.00 | E10: -- | F10: 987.02 | G10: Mobile | H10: 100004250101140046124766907091
A11: 01 Jan 2025 20:46:58 | B11: 01 Jan 2025 | C11: Transfer to POS Transfer-AMINA HARUNA | MONIE POINT | 5730253158 | D11: 500.00 | E11: -- | F11: 487.02 | G11: Mobile | H11: 100004250101204705124785870809
A12: 01 Jan 2025 20:51:11 | B12: 01 Jan 2025 | C12: Transfer to MUHAMMED OLUWATOBI ABDULSALAM | OPay | 9068533201 | D12: 100.00 | E12: -- | F12: 387.02 | G12: Mobile | H12: 250101010100640051465384
A13: 01 Jan 2025 22:10:30 | B13: 01 Jan 2025 | C13: Transfer from UMAR MUHAMMAD ABUBAKAR | Guaranty Trust Bank | 032****140 | NIP Transfer to MUHAMMAD ABUBAKAR UMAR. 000013250101231030000067145418 | D13: -- | E13: 9,900.00 | F13: 10,287.02 | G13: Mobile | H13: 000013250101231030000067145418
A14: 01 Jan 2025 22:11:06 | B14: 01 Jan 2025 | C14: Transfer from UMAR MUHAMMAD ABUBAKAR | Guaranty Trust Bank | 032****140 | NIP Transfer to MUHAMMAD ABUBAKAR UMAR. 000013250101231106000067145751 | D14: -- | E14: 5,000.00 | F14: 15,287.02 | G14: Mobile | H14: 000013250101231106000067145751
A15: 02 Jan 2025 07:33:21 | B15: 02 Jan 2025 | C15: Transfer to KHAIRAT ZUBAIRU | OPay | 7033715966 | D15: 2,000.00 | E15: -- | F15: 13,287.02 | G15: Mobile | H15: 250102010100642590690629
A16: 02 Jan 2025 07:40:54 | B16: 02 Jan 2025 | C16: Transfer to POS Transfer - IBRAHIM NAKOZI | MONIE POINT | 8173156921 | D16: 3,300.00 | E16: -- | F16: 9,987.02 | G16: Mobile | H16: 100004250102074100124792919479
A17: 02 Jan 2025 07:41:54 | B17: 02 Jan 2025 | C17: Transfer to POS Transfer - IBRAHIM NAKOZI | MONIE POINT | 8173156921 | D17: 500.00 | E17: -- | F17: 9,487.02 | G17: Mobile | H17: 100004250102074158124793509722
A18: 02 Jan 2025 08:03:00 | B18: 02 Jan 2025 | C18: Transfer to ABDULLAHI MUTTAKA | MONIE POINT | 9162038218 | D18: 100.00 | E18: -- | F18: 9,387.02 | G18: Mobile | H18: 100004250102080304124794033983
... A1889: 26 Dec 2025 20:45:17 | B1889: 26 Dec 2025 | C1889: Transfer to IBRAHIM ABDULWAHAB AHMAD | MONIE POINT | 8252517728 | D1889: 500.00 | E1889: -- | F1889: 6,318.86 | G1889: Mobile | H1889: 100004251226204521148583569147

Sheet Savings Account Transactions
A1: Savings Account Statement | E1: Date Printed | F1: 27 Dec 2025 22:27:55
A2: Account Name | B2: MUHAMMAD ABUBAKAR UMAR | C2: Account Number | D2: 8147735015 | E2: Address | F2: Danbare quarters, Opposite Buk gate, Ungogo, Ungogo, Kano
A3: Account Type | B3: Savings Account | C3: Period | D3: 01 Jan 2025-26 Dec 2025
A4: Opening Balance | B4: ₦0.00 | C4: Total Debit | D4: ₦62,064.81 | E4: Debit Count | F4: 28
A5: Closing Balance | B5: ₦0.00 | C5: Total Credit | D5: ₦62,064.81 | E5: Credit Count | F5: 21
A7: Trans. Date | B7: Value Date | C7: Description | D7: Debit(₦) | E7: Credit(₦) | F7: Balance After(₦) | G7: Channel | H7: Transaction Reference
A8: 27 Apr 2025 14:40:36 | B8: 27 Apr 2025 | C8: OWealth Deposit(from Fixed) | D8: -- | E8: 15,000.00 | F8: 15,000.00 | G8: Mobile | H8: 250427994bJBOx8QYPZQBowU0LzoOO
A9: 28 Apr 2025 10:36:30 | B9: 28 Apr 2025 | C9: OWealth Withdrawal(Transaction Payment) | D9: 1,000.00 | E9: -- | F9: 14,000.00 | G9: Mobile | H9: 250428010200418316863300
A10: 29 Apr 2025 02:54:23 | B10: 29 Apr 2025 | C10: OWealth Interest Earned | D10: -- | E10: 4.82 | F10: 14,004.82 | G10: Mobile | H10: 25042999afItiCioLpz2Fbu2GbxxW
A11: 29 Apr 2025 09:51:30 | B11: 29 Apr 2025 | C11: OWealth Withdrawal(Transaction Payment) | D11: 650.00 | E11: -- | F11: 13,354.82 | G11: Mobile | H11: 250429010200433677625903
A12: 29 Apr 2025 13:13:33 | B12: 29 Apr 2025 | C12: OWealth Withdrawal(Transaction Payment) | D12: 800.00 | E12: -- | F12: 12,554.82 | G12: Mobile | H12: 250429010200436547802803
A13: 29 Apr 2025 14:59:05 | B13: 29 Apr 2025 | C13: OWealth Withdrawal(Transaction Payment) | D13: 500.00 | E13: -- | F13: 12,054.82 | G13: Mobile | H13: 250429010200438096271443
A14: 29 Apr 2025 19:52:28 | B14: 29 Apr 2025 | C14: OWealth Withdrawal(Transaction Payment) | D14: 2,000.00 | E14: -- | F14: 10,054.82 | G14: Mobile | H14: 250429010200443587838646
A15: 30 Apr 2025 02:47:46 | B15: 30 Apr 2025 | C15: OWealth Interest Earned | D15: -- | E15: 3.46 | F15: 10,058.28 | G15: Mobile | H15: 250430993dixTLWiM7Zm8sLpBCYia7
A16: 01 May 2025 02:37:08 | B16: 01 May 2025 | C16: OWealth Interest Earned | D16: -- | E16: 3.46 | F16: 10,061.74 | G16: Mobile | H16: 2505019976yCp4VaDhItuINC2b6Tbg
A17: 01 May 2025 11:46:44 | B17: 01 May 2025 | C17: OWealth Withdrawal(Transaction Payment) | D17: 5,000.00 | E17: -- | F17: 5,061.74 | G17: Mobile | H17: 250501010200469848882800
A18: 01 May 2025 13:00:30 | B18: 01 May 2025 | C18: OWealth Deposit(from Fixed) | D18: -- | E18: 30,000.00 | F18: 35,061.74 | G18: Mobile | H18: 250501995ePRBNMXQwiK7BX9pNXzGQ
... A56: 26 Nov 2025 07:11:15 | B56: 26 Nov 2025 | C56: OWealth Withdrawal | D56: 5,001.71 | E56: -- | F56: 0.00 | G56: Mobile | H56: 251126010201854232706875

Sheet Cleaned_Data
A1: Date | B1: Month | C1: Month_number | D1: Transaction type | E1: Withdrawal | F1: Deposit | G1: Transaction_Direction | H1: Time of transaction | I1: Amount
A2: =Raw_Data!A8 -> 01 Jan 2025 04:07:19 | B2: =TEXT(A2,"MMMM") -> January | C2: =MONTH(A2) -> 1 | D2: =IFERROR(__xludf.DUMMYFUNCTION("IFERROR(IF(REGEXMATCH(LOWER(Raw_Data!C8),""fixed deposit|owealth|savings|target""),""Fixed Deposit"",IF(REGEXMATCH(LOWER(Raw_Data!C8),""airtime""),""Airtime"",IF(REGEXMATCH(LOWER(Raw_Data!C8),""electronic money transfer levy""),""Electronic Money Transfer"&" Levy"",IF(REGEXMATCH(LOWER(Raw_Data!C8),""transfer|trf|send""),""Transfer"",""Other"")))),""Other"")"),"Airtime") -> Airtime | E2: 200 | F2: 0 | G2: =IF(E2 <> 0,"Withdrawal","Deposit") -> Withdrawal | H2: =TEXT(Raw_Data!A8,"hh:mm:ss") -> 04:07:19 | I2: =IF(E2<> 0,E2,F2) -> 200
A3: =Raw_Data!A9 -> 01 Jan 2025 13:29:19 | B3: =TEXT(A3,"MMMM") -> January | C3: =MONTH(A3) -> 1 | D3: =IFERROR(__xludf.DUMMYFUNCTION("IFERROR(IF(REGEXMATCH(LOWER(Raw_Data!C9),""fixed deposit|owealth|savings|target""),""Fixed Deposit"",IF(REGEXMATCH(LOWER(Raw_Data!C9),""airtime""),""Airtime"",IF(REGEXMATCH(LOWER(Raw_Data!C9),""electronic money transfer levy""),""Electronic Money Transfer"&" Levy"",IF(REGEXMATCH(LOWER(Raw_Data!C9),""transfer|trf|send""),""Transfer"",""Other"")))),""Other"")"),"Transfer") -> Transfer | E3: 0 | F3: 300 | G3: =IF(E3 <> 0,"Withdrawal","Deposit") -> Deposit | H3: =TEXT(Raw_Data!A9,"hh:mm:ss") -> 13:29:19 | I3: =IF(E3<> 0,E3,F3) -> 300
A4: =Raw_Data!A10 -> 01 Jan 2025 14:00:41 | B4: =TEXT(A4,"MMMM") -> January | C4: =MONTH(A4) -> 1 | D4: =IFERROR(__xludf.DUMMYFUNCTION("IFERROR(IF(REGEXMATCH(LOWER(Raw_Data!C10),""fixed deposit|owealth|savings|target""),""Fixed Deposit"",IF(REGEXMATCH(LOWER(Raw_Data!C10),""airtime""),""Airtime"",IF(REGEXMATCH(LOWER(Raw_Data!C10),""electronic money transfer levy""),""Electronic Money Trans"&"fer Levy"",IF(REGEXMATCH(LOWER(Raw_Data!C10),""transfer|trf|send""),""Transfer"",""Other"")))),""Other"")"),"Transfer") -> Transfer | E4: 700 | F4: 0 | G4: =IF(E4 <> 0,"Withdrawal","Deposit") -> Withdrawal | H4: =TEXT(Raw_Data!A10,"hh:mm:ss") -> 14:00:41 | I4: =IF(E4<> 0,E4,F4) -> 700
A5: =Raw_Data!A11 -> 01 Jan 2025 20:46:58 | B5: =TEXT(A5,"MMMM") -> January | C5: =MONTH(A5) -> 1 | D5: =IFERROR(__xludf.DUMMYFUNCTION("IFERROR(IF(REGEXMATCH(LOWER(Raw_Data!C11),""fixed deposit|owealth|savings|target""),""Fixed Deposit"",IF(REGEXMATCH(LOWER(Raw_Data!C11),""airtime""),""Airtime"",IF(REGEXMATCH(LOWER(Raw_Data!C11),""electronic money transfer levy""),""Electronic Money Trans"&"fer Levy"",IF(REGEXMATCH(LOWER(Raw_Data!C11),""transfer|trf|send""),""Transfer"",""Other"")))),""Other"")"),"Transfer") -> Transfer | E5: 500 | F5: 0 | G5: =IF(E5 <> 0,"Withdrawal","Deposit") -> Withdrawal | H5: =TEXT(Raw_Data!A11,"hh:mm:ss") -> 20:46:58 | I5: =IF(E5<> 0,E5,F5) -> 500
A6: =Raw_Data!A12 -> 01 Jan 2025 20:51:11 | B6: =TEXT(A6,"MMMM") -> January | C6: =MONTH(A6) -> 1 | D6: =IFERROR(__xludf.DUMMYFUNCTION("IFERROR(IF(REGEXMATCH(LOWER(Raw_Data!C12),""fixed deposit|owealth|savings|target""),""Fixed Deposit"",IF(REGEXMATCH(LOWER(Raw_Data!C12),""airtime""),""Airtime"",IF(REGEXMATCH(LOWER(Raw_Data!C12),""electronic money transfer levy""),""Electronic Money Trans"&"fer Levy"",IF(REGEXMATCH(LOWER(Raw_Data!C12),""transfer|trf|send""),""Transfer"",""Other"")))),""Other"")"),"Transfer") -> Transfer | E6: 100 | F6: 0 | G6: =IF(E6 <> 0,"Withdrawal","Deposit") -> Withdrawal | H6: =TEXT(Raw_Data!A12,"hh:mm:ss") -> 20:51:11 | I6: =IF(E6<> 0,E6,F6) -> 100
A7: =Raw_Data!A13 -> 01 Jan 2025 22:10:30 | B7: =TEXT(A7,"MMMM") -> January | C7: =MONTH(A7) -> 1 | D7: =IFERROR(__xludf.DUMMYFUNCTION("IFERROR(IF(REGEXMATCH(LOWER(Raw_Data!C13),""fixed deposit|owealth|savings|target""),""Fixed Deposit"",IF(REGEXMATCH(LOWER(Raw_Data!C13),""airtime""),""Airtime"",IF(REGEXMATCH(LOWER(Raw_Data!C13),""electronic money transfer levy""),""Electronic Money Trans"&"fer Levy"",IF(REGEXMATCH(LOWER(Raw_Data!C13),""transfer|trf|send""),""Transfer"",""Other"")))),""Other"")"),"Transfer") -> Transfer | E7: 0 | F7: 9900 | G7: =IF(E7 <> 0,"Withdrawal","Deposit") -> Deposit | H7: =TEXT(Raw_Data!A13,"hh:mm:ss") -> 22:10:30 | I7: =IF(E7<> 0,E7,F7) -> 9900
A8: =Raw_Data!A14 -> 01 Jan 2025 22:11:06 | B8: =TEXT(A8,"MMMM") -> January | C8: =MONTH(A8) -> 1 | D8: =IFERROR(__xludf.DUMMYFUNCTION("IFERROR(IF(REGEXMATCH(LOWER(Raw_Data!C14),""fixed deposit|owealth|savings|target""),""Fixed Deposit"",IF(REGEXMATCH(LOWER(Raw_Data!C14),""airtime""),""Airtime"",IF(REGEXMATCH(LOWER(Raw_Data!C14),""electronic money transfer levy""),""Electronic Money Trans"&"fer Levy"",IF(REGEXMATCH(LOWER(Raw_Data!C14),""transfer|trf|send""),""Transfer"",""Other"")))),""Other"")"),"Transfer") -> Transfer | E8: 0 | F8: 5000 | G8: =IF(E8 <> 0,"Withdrawal","Deposit") -> Deposit | H8: =TEXT(Raw_Data!A14,"hh:mm:ss") -> 22:11:06 | I8: =IF(E8<> 0,E8,F8) -> 5000
A9: =Raw_Data!A15 -> 02 Jan 2025 07:33:21 | B9: =TEXT(A9,"MMMM") -> January | C9: =MONTH(A9) -> 1 | D9: =IFERROR(__xludf.DUMMYFUNCTION("IFERROR(IF(REGEXMATCH(LOWER(Raw_Data!C15),""fixed deposit|owealth|savings|target""),""Fixed Deposit"",IF(REGEXMATCH(LOWER(Raw_Data!C15),""airtime""),""Airtime"",IF(REGEXMATCH(LOWER(Raw_Data!C15),""electronic money transfer levy""),""Electronic Money Trans"&"fer Levy"",IF(REGEXMATCH(LOWER(Raw_Data!C15),""transfer|trf|send""),""Transfer"",""Other"")))),""Other"")"),"Transfer") -> Transfer | E9: 2000 | F9: 0 | G9: =IF(E9 <> 0,"Withdrawal","Deposit") -> Withdrawal | H9: =TEXT(Raw_Data!A15,"hh:mm:ss") -> 07:33:21 | I9: =IF(E9<> 0,E9,F9) -> 2000
A10: =Raw_Data!A16 -> 02 Jan 2025 07:40:54 | B10: =TEXT(A10,"MMMM") -> January | C10: =MONTH(A10) -> 1 | D10: =IFERROR(__xludf.DUMMYFUNCTION("IFERROR(IF(REGEXMATCH(LOWER(Raw_Data!C16),""fixed deposit|owealth|savings|target""),""Fixed Deposit"",IF(REGEXMATCH(LOWER(Raw_Data!C16),""airtime""),""Airtime"",IF(REGEXMATCH(LOWER(Raw_Data!C16),""electronic money transfer levy""),""Electronic Money Trans"&"fer Levy"",IF(REGEXMATCH(LOWER(Raw_Data!C16),""transfer|trf|send""),""Transfer"",""Other"")))),""Other"")"),"Transfer") -> Transfer | E10: 3300 | F10: 0 | G10: =IF(E10 <> 0,"Withdrawal","Deposit") -> Withdrawal | H10: =TEXT(Raw_Data!A16,"hh:mm:ss") -> 07:40:54 | I10: =IF(E10<> 0,E10,F10) -> 3300
A11: =Raw_Data!A17 -> 02 Jan 2025 07:41:54 | B11: =TEXT(A11,"MMMM") -> January | C11: =MONTH(A11) -> 1 | D11: =IFERROR(__xludf.DUMMYFUNCTION("IFERROR(IF(REGEXMATCH(LOWER(Raw_Data!C17),""fixed deposit|owealth|savings|target""),""Fixed Deposit"",IF(REGEXMATCH(LOWER(Raw_Data!C17),""airtime""),""Airtime"",IF(REGEXMATCH(LOWER(Raw_Data!C17),""electronic money transfer levy""),""Electronic Money Trans"&"fer Levy"",IF(REGEXMATCH(LOWER(Raw_Data!C17),""transfer|trf|send""),""Transfer"",""Other"")))),""Other"")"),"Transfer") -> Transfer | E11: 500 | F11: 0 | G11: =IF(E11 <> 0,"Withdrawal","Deposit") -> Withdrawal | H11: =TEXT(Raw_Data!A17,"hh:mm:ss") -> 07:41:54 | I11: =IF(E11<> 0,E11,F11) -> 500
A12: =Raw_Data!A18 -> 02 Jan 2025 08:03:00 | B12: =TEXT(A12,"MMMM") -> January | C12: =MONTH(A12) -> 1 | D12: =IFERROR(__xludf.DUMMYFUNCTION("IFERROR(IF(REGEXMATCH(LOWER(Raw_Data!C18),""fixed deposit|owealth|savings|target""),""Fixed Deposit"",IF(REGEXMATCH(LOWER(Raw_Data!C18),""airtime""),""Airtime"",IF(REGEXMATCH(LOWER(Raw_Data!C18),""electronic money transfer levy""),""Electronic Money Trans"&"fer Levy"",IF(REGEXMATCH(LOWER(Raw_Data!C18),""transfer|trf|send""),""Transfer"",""Other"")))),""Other"")"),"Transfer") -> Transfer | E12: 100 | F12: 0 | G12: =IF(E12 <> 0,"Withdrawal","Deposit") -> Withdrawal | H12: =TEXT(Raw_Data!A18,"hh:mm:ss") -> 08:03:00 | I12: =IF(E12<> 0,E12,F12) -> 100
A13: =Raw_Data!A19 -> 02 Jan 2025 12:16:34 | B13: =TEXT(A13,"MMMM") -> January | C13: =MONTH(A13) -> 1 | D13: =IFERROR(__xludf.DUMMYFUNCTION("IFERROR(IF(REGEXMATCH(LOWER(Raw_Data!C19),""fixed deposit|owealth|savings|target""),""Fixed Deposit"",IF(REGEXMATCH(LOWER(Raw_Data!C19),""airtime""),""Airtime"",IF(REGEXMATCH(LOWER(Raw_Data!C19),""electronic money transfer levy""),""Electronic Money Trans"&"fer Levy"",IF(REGEXMATCH(LOWER(Raw_Data!C19),""transfer|trf|send""),""Transfer"",""Other"")))),""Other"")"),"Transfer") -> Transfer | E13: 1410 | F13: 0 | G13: =IF(E13 <> 0,"Withdrawal","Deposit") -> Withdrawal | H13: =TEXT(Raw_Data!A19,"hh:mm:ss") -> 12:16:34 | I13: =IF(E13<> 0,E13,F13) -> 1410
A14: =Raw_Data!A20 -> 02 Jan 2025 16:19:54 | B14: =TEXT(A14,"MMMM") -> January | C14: =MONTH(A14) -> 1 | D14: =IFERROR(__xludf.DUMMYFUNCTION("IFERROR(IF(REGEXMATCH(LOWER(Raw_Data!C20),""fixed deposit|owealth|savings|target""),""Fixed Deposit"",IF(REGEXMATCH(LOWER(Raw_Data!C20),""airtime""),""Airtime"",IF(REGEXMATCH(LOWER(Raw_Data!C20),""electronic money transfer levy""),""Electronic Money Trans"&"fer Levy"",IF(REGEXMATCH(LOWER(Raw_Data!C20),""transfer|trf|send""),""Transfer"",""Other"")))),""Other"")"),"Transfer") -> Transfer | E14: 200 | F14: 0 | G14: =IF(E14 <> 0,"Withdrawal","Deposit") -> Withdrawal | H14: =TEXT(Raw_Data!A20,"hh:mm:ss") -> 16:19:54 | I14: =IF(E14<> 0,E14,F14) -> 200
A15: =Raw_Data!A21 -> 02 Jan 2025 20:04:55 | B15: =TEXT(A15,"MMMM") -> January | C15: =MONTH(A15) -> 1 | D15: =IFERROR(__xludf.DUMMYFUNCTION("IFERROR(IF(REGEXMATCH(LOWER(Raw_Data!C21),""fixed deposit|owealth|savings|target""),""Fixed Deposit"",IF(REGEXMATCH(LOWER(Raw_Data!C21),""airtime""),""Airtime"",IF(REGEXMATCH(LOWER(Raw_Data!C21),""electronic money transfer levy""),""Electronic Money Trans"&"fer Levy"",IF(REGEXMATCH(LOWER(Raw_Data!C21),""transfer|trf|send""),""Transfer"",""Other"")))),""Other"")"),"Transfer") -> Transfer | E15: 0 | F15: 1000 | G15: =IF(E15 <> 0,"Withdrawal","Deposit") -> Deposit | H15: =TEXT(Raw_Data!A21,"hh:mm:ss") -> 20:04:55 | I15: =IF(E15<> 0,E15,F15) -> 1000
A16: =Raw_Data!A22 -> 02 Jan 2025 20:17:14 | B16: =TEXT(A16,"MMMM") -> January | C16: =MONTH(A16) -> 1 | D16: =IFERROR(__xludf.DUMMYFUNCTION("IFERROR(IF(REGEXMATCH(LOWER(Raw_Data!C22),""fixed deposit|owealth|savings|target""),""Fixed Deposit"",IF(REGEXMATCH(LOWER(Raw_Data!C22),""airtime""),""Airtime"",IF(REGEXMATCH(LOWER(Raw_Data!C22),""electronic money transfer levy""),""Electronic Money Trans"&"fer Levy"",IF(REGEXMATCH(LOWER(Raw_Data!C22),""transfer|trf|send""),""Transfer"",""Other"")))),""Other"")"),"Transfer") -> Transfer | E16: 2110 | F16: 0 | G16: =IF(E16 <> 0,"Withdrawal","Deposit") -> Withdrawal | H16: =TEXT(Raw_Data!A22,"hh:mm:ss") -> 20:17:14 | I16: =IF(E16<> 0,E16,F16) -> 2110
A17: =Raw_Data!A23 -> 03 Jan 2025 09:44:30 | B17: =TEXT(A17,"MMMM") -> January | C17: =MONTH(A17) -> 1 | D17: =IFERROR(__xludf.DUMMYFUNCTION("IFERROR(IF(REGEXMATCH(LOWER(Raw_Data!C23),""fixed deposit|owealth|savings|target""),""Fixed Deposit"",IF(REGEXMATCH(LOWER(Raw_Data!C23),""airtime""),""Airtime"",IF(REGEXMATCH(LOWER(Raw_Data!C23),""electronic money transfer levy""),""Electronic Money Trans"&"fer Levy"",IF(REGEXMATCH(LOWER(Raw_Data!C23),""transfer|trf|send""),""Transfer"",""Other"")))),""Other"")"),"Transfer") -> Transfer | E17: 1050 | F17: 0 | G17: =IF(E17 <> 0,"Withdrawal","Deposit") -> Withdrawal | H17: =TEXT(Raw_Data!A23,"hh:mm:ss") -> 09:44:30 | I17: =IF(E17<> 0,E17,F17) -> 1050
A18: =Raw_Data!A24 -> 03 Jan 2025 11:02:53 | B18: =TEXT(A18,"MMMM") -> January | C18: =MONTH(A18) -> 1 | D18: =IFERROR(__xludf.DUMMYFUNCTION("IFERROR(IF(REGEXMATCH(LOWER(Raw_Data!C24),""fixed deposit|owealth|savings|target""),""Fixed Deposit"",IF(REGEXMATCH(LOWER(Raw_Data!C24),""airtime""),""Airtime"",IF(REGEXMATCH(LOWER(Raw_Data!C24),""electronic money transfer levy""),""Electronic Money Trans"&"fer Levy"",IF(REGEXMATCH(LOWER(Raw_Data!C24),""transfer|trf|send""),""Transfer"",""Other"")))),""Other"")"),"Airtime") -> Airtime | E18: 200 | F18: 0 | G18: =IF(E18 <> 0,"Withdrawal","Deposit") -> Withdrawal | H18: =TEXT(Raw_Data!A24,"hh:mm:ss") -> 11:02:53 | I18: =IF(E18<> 0,E18,F18) -> 200
A19: =Raw_Data!A25 -> 03 Jan 2025 11:29:36 | B19: =TEXT(A19,"MMMM") -> January | C19: =MONTH(A19) -> 1 | D19: =IFERROR(__xludf.DUMMYFUNCTION("IFERROR(IF(REGEXMATCH(LOWER(Raw_Data!C25),""fixed deposit|owealth|savings|target""),""Fixed Deposit"",IF(REGEXMATCH(LOWER(Raw_Data!C25),""airtime""),""Airtime"",IF(REGEXMATCH(LOWER(Raw_Data!C25),""electronic money transfer levy""),""Electronic Money Trans"&"fer Levy"",IF(REGEXMATCH(LOWER(Raw_Data!C25),""transfer|trf|send""),""Transfer"",""Other"")))),""Other"")"),"Transfer") -> Transfer | E19: 1000 | F19: 0 | G19: =IF(E19 <> 0,"Withdrawal","Deposit") -> Withdrawal | H19: =TEXT(Raw_Data!A25,"hh:mm:ss") -> 11:29:36 | I19: =IF(E19<> 0,E19,F19) -> 1000
A20: =Raw_Data!A26 -> 03 Jan 2025 12:55:56 | B20: =TEXT(A20,"MMMM") -> January | C20: =MONTH(A20) -> 1 | D20: =IFERROR(__xludf.DUMMYFUNCTION("IFERROR(IF(REGEXMATCH(LOWER(Raw_Data!C26),""fixed deposit|owealth|savings|target""),""Fixed Deposit"",IF(REGEXMATCH(LOWER(Raw_Data!C26),""airtime""),""Airtime"",IF(REGEXMATCH(LOWER(Raw_Data!C26),""electronic money transfer levy""),""Electronic Money Trans"&"fer Levy"",IF(REGEXMATCH(LOWER(Raw_Data!C26),""transfer|trf|send""),""Transfer"",""Other"")))),""Other"")"),"Transfer") -> Transfer | E20: 250 | F20: 0 | G20: =IF(E20 <> 0,"Withdrawal","Deposit") -> Withdrawal | H20: =TEXT(Raw_Data!A26,"hh:mm:ss") -> 12:55:56 | I20: =IF(E20<> 0,E20,F20) -> 250
A21: =Raw_Data!A27 -> 03 Jan 2025 16:09:32 | B21: =TEXT(A21,"MMMM") -> January | C21: =MONTH(A21) -> 1 | D21: =IFERROR(__xludf.DUMMYFUNCTION("IFERROR(IF(REGEXMATCH(LOWER(Raw_Data!C27),""fixed deposit|owealth|savings|target""),""Fixed Deposit"",IF(REGEXMATCH(LOWER(Raw_Data!C27),""airtime""),""Airtime"",IF(REGEXMATCH(LOWER(Raw_Data!C27),""electronic money transfer levy""),""Electronic Money Trans"&"fer Levy"",IF(REGEXMATCH(LOWER(Raw_Data!C27),""transfer|trf|send""),""Transfer"",""Other"")))),""Other"")"),"Transfer") -> Transfer | E21: 600 | F21: 0 | G21: =IF(E21 <> 0,"Withdrawal","Deposit") -> Withdrawal | H21: =TEXT(Raw_Data!A27,"hh:mm:ss") -> 16:09:32 | I21: =IF(E21<> 0,E21,F21) -> 600
A22: =Raw_Data!A28 -> 03 Jan 2025 23:32:01 | B22: =TEXT(A22,"MMMM") -> January | C22: =MONTH(A22) -> 1 | D22: =IFERROR(__xludf.DUMMYFUNCTION("IFERROR(IF(REGEXMATCH(LOWER(Raw_Data!C28),""fixed deposit|owealth|savings|target""),""Fixed Deposit"",IF(REGEXMATCH(LOWER(Raw_Data!C28),""airtime""),""Airtime"",IF(REGEXMATCH(LOWER(Raw_Data!C28),""electronic money transfer levy""),""Electronic Money Trans"&"fer Levy"",IF(REGEXMATCH(LOWER(Raw_Data!C28),""transfer|trf|send""),""Transfer"",""Other"")))),""Other"")"),"Transfer") -> Transfer | E22: 0 | F22: 9999 | G22: =IF(E22 <> 0,"Withdrawal","Deposit") -> Deposit | H22: =TEXT(Raw_Data!A28,"hh:mm:ss") -> 23:32:01 | I22: =IF(E22<> 0,E22,F22) -> 9999
A23: =Raw_Data!A29 -> 03 Jan 2025 23:32:22 | B23: =TEXT(A23,"MMMM") -> January | C23: =MONTH(A23) -> 1 | D23: =IFERROR(__xludf.DUMMYFUNCTION("IFERROR(IF(REGEXMATCH(LOWER(Raw_Data!C29),""fixed deposit|owealth|savings|target""),""Fixed Deposit"",IF(REGEXMATCH(LOWER(Raw_Data!C29),""airtime""),""Airtime"",IF(REGEXMATCH(LOWER(Raw_Data!C29),""electronic money transfer levy""),""Electronic Money Trans"&"fer Levy"",IF(REGEXMATCH(LOWER(Raw_Data!C29),""transfer|trf|send""),""Transfer"",""Other"")))),""Other"")"),"Transfer") -> Transfer | E23: 0 | F23: 5001 | G23: =IF(E23 <> 0,"Withdrawal","Deposit") -> Deposit | H23: =TEXT(Raw_Data!A29,"hh:mm:ss") -> 23:32:22 | I23: =IF(E23<> 0,E23,F23) -> 5001
A24: =Raw_Data!A30 -> 03 Jan 2025 23:35:03 | B24: =TEXT(A24,"MMMM") -> January | C24: =MONTH(A24) -> 1 | D24: =IFERROR(__xludf.DUMMYFUNCTION("IFERROR(IF(REGEXMATCH(LOWER(Raw_Data!C30),""fixed deposit|owealth|savings|target""),""Fixed Deposit"",IF(REGEXMATCH(LOWER(Raw_Data!C30),""airtime""),""Airtime"",IF(REGEXMATCH(LOWER(Raw_Data!C30),""electronic money transfer levy""),""Electronic Money Trans"&"fer Levy"",IF(REGEXMATCH(LOWER(Raw_Data!C30),""transfer|trf|send""),""Transfer"",""Other"")))),""Other"")"),"Transfer") -> Transfer | E24: 12000 | F24: 0 | G24: =IF(E24 <> 0,"Withdrawal","Deposit") -> Withdrawal | H24: =TEXT(Raw_Data!A30,"hh:mm:ss") -> 23:35:03 | I24: =IF(E24<> 0,E24,F24) -> 12000
A25: =Raw_Data!A31 -> 04 Jan 2025 08:19:48 | B25: =TEXT(A25,"MMMM") -> January | C25: =MONTH(A25) -> 1 | D25: =IFERROR(__xludf.DUMMYFUNCTION("IFERROR(IF(REGEXMATCH(LOWER(Raw_Data!C31),""fixed deposit|owealth|savings|target""),""Fixed Deposit"",IF(REGEXMATCH(LOWER(Raw_Data!C31),""airtime""),""Airtime"",IF(REGEXMATCH(LOWER(Raw_Data!C31),""electronic money transfer levy""),""Electronic Money Trans"&"fer Levy"",IF(REGEXMATCH(LOWER(Raw_Data!C31),""transfer|trf|send""),""Transfer"",""Other"")))),""Other"")"),"Transfer") -> Transfer | E25: 300 | F25: 0 | G25: =IF(E25 <> 0,"Withdrawal","Deposit") -> Withdrawal | H25: =TEXT(Raw_Data!A31,"hh:mm:ss") -> 08:19:48 | I25: =IF(E25<> 0,E25,F25) -> 300
A26: =Raw_Data!A32 -> 04 Jan 2025 09:16:10 | B26: =TEXT(A26,"MMMM") -> January | C26: =MONTH(A26) -> 1 | D26: =IFERROR(__xludf.DUMMYFUNCTION("IFERROR(IF(REGEXMATCH(LOWER(Raw_Data!C32),""fixed deposit|owealth|savings|target""),""Fixed Deposit"",IF(REGEXMATCH(LOWER(Raw_Data!C32),""airtime""),""Airtime"",IF(REGEXMATCH(LOWER(Raw_Data!C32),""electronic money transfer levy""),""Electronic Money Trans"&"fer Levy"",IF(REGEXMATCH(LOWER(Raw_Data!C32),""transfer|trf|send""),""Transfer"",""Other"")))),""Other"")"),"Transfer") -> Transfer | E26: 0 | F26: 300 | G26: =IF(E26 <> 0,"Withdrawal","Deposit") -> Deposit | H26: =TEXT(Raw_Data!A32,"hh:mm:ss") -> 09:16:10 | I26: =IF(E26<> 0,E26,F26) -> 300
A27: =Raw_Data!A33 -> 04 Jan 2025 09:38:25 | B27: =TEXT(A27,"MMMM") -> January | C27: =MONTH(A27) -> 1 | D27: =IFERROR(__xludf.DUMMYFUNCTION("IFERROR(IF(REGEXMATCH(LOWER(Raw_Data!C33),""fixed deposit|owealth|savings|target""),""Fixed Deposit"",IF(REGEXMATCH(LOWER(Raw_Data!C33),""airtime""),""Airtime"",IF(REGEXMATCH(LOWER(Raw_Data!C33),""electronic money transfer levy""),""Electronic Money Trans"&"fer Levy"",IF(REGEXMATCH(LOWER(Raw_Data!C33),""transfer|trf|send""),""Transfer"",""Other"")))),""Other"")"),"Transfer") -> Transfer | E27: 2150 | F27: 0 | G27: =IF(E27 <> 0,"Withdrawal","Deposit") -> Withdrawal | H27: =TEXT(Raw_Data!A33,"hh:mm:ss") -> 09:38:25 | I27: =IF(E27<> 0,E27,F27) -> 2150
A28: =Raw_Data!A34 -> 04 Jan 2025 09:43:27 | B28: =TEXT(A28,"MMMM") -> January | C28: =MONTH(A28) -> 1 | D28: =IFERROR(__xludf.DUMMYFUNCTION("IFERROR(IF(REGEXMATCH(LOWER(Raw_Data!C34),""fixed deposit|owealth|savings|target""),""Fixed Deposit"",IF(REGEXMATCH(LOWER(Raw_Data!C34),""airtime""),""Airtime"",IF(REGEXMATCH(LOWER(Raw_Data!C34),""electronic money transfer levy""),""Electronic Money Trans"&"fer Levy"",IF(REGEXMATCH(LOWER(Raw_Data!C34),""transfer|trf|send""),""Transfer"",""Other"")))),""Other"")"),"Transfer") -> Transfer | E28: 1820 | F28: 0 | G28: =IF(E28 <> 0,"Withdrawal","Deposit") -> Withdrawal | H28: =TEXT(Raw_Data!A34,"hh:mm:ss") -> 09:43:27 | I28: =IF(E28<> 0,E28,F28) -> 1820
A29: =Raw_Data!A35 -> 04 Jan 2025 11:33:54 | B29: =TEXT(A29,"MMMM") -> January | C29: =MONTH(A29) -> 1 | D29: =IFERROR(__xludf.DUMMYFUNCTION("IFERROR(IF(REGEXMATCH(LOWER(Raw_Data!C35),""fixed deposit|owealth|savings|target""),""Fixed Deposit"",IF(REGEXMATCH(LOWER(Raw_Data!C35),""airtime""),""Airtime"",IF(REGEXMATCH(LOWER(Raw_Data!C35),""electronic money transfer levy""),""Electronic Money Trans"&"fer Levy"",IF(REGEXMATCH(LOWER(Raw_Data!C35),""transfer|trf|send""),""Transfer"",""Other"")))),""Other"")"),"Airtime") -> Airtime | E29: 500 | F29: 0 | G29: =IF(E29 <> 0,"Withdrawal","Deposit") -> Withdrawal | H29: =TEXT(Raw_Data!A35,"hh:mm:ss") -> 11:33:54 | I29: =IF(E29<> 0,E29,F29) -> 500
A30: =Raw_Data!A36 -> 04 Jan 2025 15:28:50 | B30: =TEXT(A30,"MMMM") -> January | C30: =MONTH(A30) -> 1 | D30: =IFERROR(__xludf.DUMMYFUNCTION("IFERROR(IF(REGEXMATCH(LOWER(Raw_Data!C36),""fixed deposit|owealth|savings|target""),""Fixed Deposit"",IF(REGEXMATCH(LOWER(Raw_Data!C36),""airtime""),""Airtime"",IF(REGEXMATCH(LOWER(Raw_Data!C36),""electronic money transfer levy""),""Electronic Money Trans"&"fer Levy"",IF(REGEXMATCH(LOWER(Raw_Data!C36),""transfer|trf|send""),""Transfer"",""Other"")))),""Other"")"),"Transfer") -> Transfer | E30: 300 | F30: 0 | G30: =IF(E30 <> 0,"Withdrawal","Deposit") -> Withdrawal | H30: =TEXT(Raw_Data!A36,"hh:mm:ss") -> 15:28:50 | I30: =IF(E30<> 0,E30,F30) -> 300
A31: =Raw_Data!A37 -> 05 Jan 2025 11:21:19 | B31: =TEXT(A31,"MMMM") -> January | C31: =MONTH(A31) -> 1 | D31: =IFERROR(__xludf.DUMMYFUNCTION("IFERROR(IF(REGEXMATCH(LOWER(Raw_Data!C37),""fixed deposit|owealth|savings|target""),""Fixed Deposit"",IF(REGEXMATCH(LOWER(Raw_Data!C37),""airtime""),""Airtime"",IF(REGEXMATCH(LOWER(Raw_Data!C37),""electronic money transfer levy""),""Electronic Money Trans"&"fer Levy"",IF(REGEXMATCH(LOWER(Raw_Data!C37),""transfer|trf|send""),""Transfer"",""Other"")))),""Other"")"),"Transfer") -> Transfer | E31: 700 | F31: 0 | G31: =IF(E31 <> 0,"Withdrawal","Deposit") -> Withdrawal | H31: =TEXT(Raw_Data!A37,"hh:mm:ss") -> 11:21:19 | I31: =IF(E31<> 0,E31,F31) -> 700
A32: =Raw_Data!A38 -> 05 Jan 2025 18:44:12 | B32: =TEXT(A32,"MMMM") -> January | C32: =MONTH(A32) -> 1 | D32: =IFERROR(__xludf.DUMMYFUNCTION("IFERROR(IF(REGEXMATCH(LOWER(Raw_Data!C38),""fixed deposit|owealth|savings|target""),""Fixed Deposit"",IF(REGEXMATCH(LOWER(Raw_Data!C38),""airtime""),""Airtime"",IF(REGEXMATCH(LOWER(Raw_Data!C38),""electronic money transfer levy""),""Electronic Money Trans"&"fer Levy"",IF(REGEXMATCH(LOWER(Raw_Data!C38),""transfer|trf|send""),""Transfer"",""Other"")))),""Other"")"),"Transfer") -> Transfer | E32: 0 | F32: 5000 | G32: =IF(E32 <> 0,"Withdrawal","Deposit") -> Deposit | H32: =TEXT(Raw_Data!A38,"hh:mm:ss") -> 18:44:12 | I32: =IF(E32<> 0,E32,F32) -> 5000
A33: =Raw_Data!A39 -> 05 Jan 2025 19:02:58 | B33: =TEXT(A33,"MMMM") -> January | C33: =MONTH(A33) -> 1 | D33: =IFERROR(__xludf.DUMMYFUNCTION("IFERROR(IF(REGEXMATCH(LOWER(Raw_Data!C39),""fixed deposit|owealth|savings|target""),""Fixed Deposit"",IF(REGEXMATCH(LOWER(Raw_Data!C39),""airtime""),""Airtime"",IF(REGEXMATCH(LOWER(Raw_Data!C39),""electronic money transfer levy""),""Electronic Money Trans"&"fer Levy"",IF(REGEXMATCH(LOWER(Raw_Data!C39),""transfer|trf|send""),""Transfer"",""Other"")))),""Other"")"),"Transfer") -> Transfer | E33: 200 | F33: 0 | G33: =IF(E33 <> 0,"Withdrawal","Deposit") -> Withdrawal | H33: =TEXT(Raw_Data!A39,"hh:mm:ss") -> 19:02:58 | I33: =IF(E33<> 0,E33,F33) -> 200
A34: =Raw_Data!A40 -> 05 Jan 2025 19:08:44 | B34: =TEXT(A34,"MMMM") -> January | C34: =MONTH(A34) -> 1 | D34: =IFERROR(__xludf.DUMMYFUNCTION("IFERROR(IF(REGEXMATCH(LOWER(Raw_Data!C40),""fixed deposit|owealth|savings|target""),""Fixed Deposit"",IF(REGEXMATCH(LOWER(Raw_Data!C40),""airtime""),""Airtime"",IF(REGEXMATCH(LOWER(Raw_Data!C40),""electronic money transfer levy""),""Electronic Money Trans"&"fer Levy"",IF(REGEXMATCH(LOWER(Raw_Data!C40),""transfer|trf|send""),""Transfer"",""Other"")))),""Other"")"),"Transfer") -> Transfer | E34: 1650 | F34: 0 | G34: =IF(E34 <> 0,"Withdrawal","Deposit") -> Withdrawal | H34: =TEXT(Raw_Data!A40,"hh:mm:ss") -> 19:08:44 | I34: =IF(E34<> 0,E34,F34) -> 1650
A35: =Raw_Data!A41 -> 05 Jan 2025 19:09:46 | B35: =TEXT(A35,"MMMM") -> January | C35: =MONTH(A35) -> 1 | D35: =IFERROR(__xludf.DUMMYFUNCTION("IFERROR(IF(REGEXMATCH(LOWER(Raw_Data!C41),""fixed deposit|owealth|savings|target""),""Fixed Deposit"",IF(REGEXMATCH(LOWER(Raw_Data!C41),""airtime""),""Airtime"",IF(REGEXMATCH(LOWER(Raw_Data!C41),""electronic money transfer levy""),""Electronic Money Trans"&"fer Levy"",IF(REGEXMATCH(LOWER(Raw_Data!C41),""transfer|trf|send""),""Transfer"",""Other"")))),""Other"")"),"Airtime") -> Airtime | E35: 500 | F35: 0 | G35: =IF(E35 <> 0,"Withdrawal","Deposit") -> Withdrawal | H35: =TEXT(Raw_Data!A41,"hh:mm:ss") -> 19:09:46 | I35: =IF(E35<> 0,E35,F35) -> 500
A36: =Raw_Data!A42 -> 05 Jan 2025 20:03:09 | B36: =TEXT(A36,"MMMM") -> January | C36: =MONTH(A36) -> 1 | D36: =IFERROR(__xludf.DUMMYFUNCTION("IFERROR(IF(REGEXMATCH(LOWER(Raw_Data!C42),""fixed deposit|owealth|savings|target""),""Fixed Deposit"",IF(REGEXMATCH(LOWER(Raw_Data!C42),""airtime""),""Airtime"",IF(REGEXMATCH(LOWER(Raw_Data!C42),""electronic money transfer levy""),""Electronic Money Trans"&"fer Levy"",IF(REGEXMATCH(LOWER(Raw_Data!C42),""transfer|trf|send""),""Transfer"",""Other"")))),""Other"")"),"Transfer") -> Transfer | E36: 900 | F36: 0 | G36: =IF(E36 <> 0,"Withdrawal","Deposit") -> Withdrawal | H36: =TEXT(Raw_Data!A42,"hh:mm:ss") -> 20:03:09 | I36: =IF(E36<> 0,E36,F36) -> 900
A37: =Raw_Data!A43 -> 06 Jan 2025 06:28:49 | B37: =TEXT(A37,"MMMM") -> January | C37: =MONTH(A37) -> 1 | D37: =IFERROR(__xludf.DUMMYFUNCTION("IFERROR(IF(REGEXMATCH(LOWER(Raw_Data!C43),""fixed deposit|owealth|savings|target""),""Fixed Deposit"",IF(REGEXMATCH(LOWER(Raw_Data!C43),""airtime""),""Airtime"",IF(REGEXMATCH(LOWER(Raw_Data!C43),""electronic money transfer levy""),""Electronic Money Trans"&"fer Levy"",IF(REGEXMATCH(LOWER(Raw_Data!C43),""transfer|trf|send""),""Transfer"",""Other"")))),""Other"")"),"Transfer") -> Transfer | E37: 0 | F37: 1500 | G37: =IF(E37 <> 0,"Withdrawal","Deposit") -> Deposit | H37: =TEXT(Raw_Data!A43,"hh:mm:ss") -> 06:28:49 | I37: =IF(E37<> 0,E37,F37) -> 1500
A38: =Raw_Data!A44 -> 06 Jan 2025 10:04:58 | B38: =TEXT(A38,"MMMM") -> January | C38: =MONTH(A38) -> 1 | D38: =IFERROR(__xludf.DUMMYFUNCTION("IFERROR(IF(REGEXMATCH(LOWER(Raw_Data!C44),""fixed deposit|owealth|savings|target""),""Fixed Deposit"",IF(REGEXMATCH(LOWER(Raw_Data!C44),""airtime""),""Airtime"",IF(REGEXMATCH(LOWER(Raw_Data!C44),""electronic money transfer levy""),""Electronic Money Trans"&"fer Levy"",IF(REGEXMATCH(LOWER(Raw_Data!C44),""transfer|trf|send""),""Transfer"",""Other"")))),""Other"")"),"Transfer") -> Transfer | E38: 200 | F38: 0 | G38: =IF(E38 <> 0,"Withdrawal","Deposit") -> Withdrawal | H38: =TEXT(Raw_Data!A44,"hh:mm:ss") -> 10:04:58 | I38: =IF(E38<> 0,E38,F38) -> 200
A39: =Raw_Data!A45 -> 06 Jan 2025 10:47:07 | B39: =TEXT(A39,"MMMM") -> January | C39: =MONTH(A39) -> 1 | D39: =IFERROR(__xludf.DUMMYFUNCTION("IFERROR(IF(REGEXMATCH(LOWER(Raw_Data!C45),""fixed deposit|owealth|savings|target""),""Fixed Deposit"",IF(REGEXMATCH(LOWER(Raw_Data!C45),""airtime""),""Airtime"",IF(REGEXMATCH(LOWER(Raw_Data!C45),""electronic money transfer levy""),""Electronic Money Trans"&"fer Levy"",IF(REGEXMATCH(LOWER(Raw_Data!C45),""transfer|trf|send""),""Transfer"",""Other"")))),""Other"")"),"Transfer") -> Transfer | E39: 2000 | F39: 0 | G39: =IF(E39 <> 0,"Withdrawal","Deposit") -> Withdrawal | H39: =TEXT(Raw_Data!A45,"hh:mm:ss") -> 10:47:07 | I39: =IF(E39<> 0,E39,F39) -> 2000
A40: =Raw_Data!A46 -> 06 Jan 2025 12:31:34 | B40: =TEXT(A40,"MMMM") -> January | C40: =MONTH(A40) -> 1 | D40: =IFERROR(__xludf.DUMMYFUNCTION("IFERROR(IF(REGEXMATCH(LOWER(Raw_Data!C46),""fixed deposit|owealth|savings|target""),""Fixed Deposit"",IF(REGEXMATCH(LOWER(Raw_Data!C46),""airtime""),""Airtime"",IF(REGEXMATCH(LOWER(Raw_Data!C46),""electronic money transfer levy""),""Electronic Money Trans"&"fer Levy"",IF(REGEXMATCH(LOWER(Raw_Data!C46),""transfer|trf|send""),""Transfer"",""Other"")))),""Other"")"),"Transfer") -> Transfer | E40: 200 | F40: 0 | G40: =IF(E40 <> 0,"Withdrawal","Deposit") -> Withdrawal | H40: =TEXT(Raw_Data!A46,"hh:mm:ss") -> 12:31:34 | I40: =IF(E40<> 0,E40,F40) -> 200
...

Sheet Pivot_Monthly

Sheet Monthly_Summary
A1: Months | B1: Total Deposits | C1: Total Withdrawals | D1: Net_Cash_Flow
A2: January | B2: =SUMIFS(Cleaned_Data!F:F,Cleaned_Data!B:B, A2,Cleaned_Data!G:G,"Deposit") -> 1063571 | C2: =SUMIFS(Cleaned_Data!E:E,Cleaned_Data!B:B, A2,Cleaned_Data!G:G,"Withdrawal") -> 1065070.9 | D2: =B2 - C2 -> -1499.92 | H2: Category Total Amount | I2: Amount
A3: February | B3: =SUMIFS(Cleaned_Data!F:F,Cleaned_Data!B:B, A3,Cleaned_Data!G:G,"Deposit") -> 507767 | C3: =SUMIFS(Cleaned_Data!E:E,Cleaned_Data!B:B, A3,Cleaned_Data!G:G,"Withdrawal") -> 505090 | D3: =B3 - C3 -> 2677 | H3: Transfer | I3: =SUMIFS(Cleaned_Data!I:I, Cleaned_Data!D:D, H3) -> 11221863
A4: March | B4: =SUMIFS(Cleaned_Data!F:F,Cleaned_Data!B:B, A4,Cleaned_Data!G:G,"Deposit") -> 461251 | C4: =SUMIFS(Cleaned_Data!E:E,Cleaned_Data!B:B, A4,Cleaned_Data!G:G,"Withdrawal") -> 458331 | D4: =B4 - C4 -> 2920 | H4: Airtime | I4: =SUMIFS(Cleaned_Data!I:I, Cleaned_Data!D:D, H4) -> 245113.65
A5: April | B5: =SUMIFS(Cleaned_Data!F:F,Cleaned_Data!B:B, A5,Cleaned_Data!G:G,"Deposit") -> 1558832 | C5: =SUMIFS(Cleaned_Data!E:E,Cleaned_Data!B:B, A5,Cleaned_Data!G:G,"Withdrawal") -> 1562230 | D5: =B5 - C5 -> -3398 | H5: Fixed Deposit | I5: =SUMIFS(Cleaned_Data!I:I, Cleaned_Data!D:D, H5) -> 124064.81
A6: May | B6: =SUMIFS(Cleaned_Data!F:F,Cleaned_Data!B:B, A6,Cleaned_Data!G:G,"Deposit") -> 364162.19 | C6: =SUMIFS(Cleaned_Data!E:E,Cleaned_Data!B:B, A6,Cleaned_Data!G:G,"Withdrawal") -> 365960 | D6: =B6 - C6 -> -1797.81 | H6: Electronic Money Transfer Levy | I6: =SUMIFS(Cleaned_Data!I:I, Cleaned_Data!D:D, H6) -> 4750
A7: June | B7: =SUMIFS(Cleaned_Data!F:F,Cleaned_Data!B:B, A7,Cleaned_Data!G:G,"Deposit") -> 499866 | C7: =SUMIFS(Cleaned_Data!E:E,Cleaned_Data!B:B, A7,Cleaned_Data!G:G,"Withdrawal") -> 494279.9 | D7: =B7 - C7 -> 5586.1
A8: July | B8: =SUMIFS(Cleaned_Data!F:F,Cleaned_Data!B:B, A8,Cleaned_Data!G:G,"Deposit") -> 105900 | C8: =SUMIFS(Cleaned_Data!E:E,Cleaned_Data!B:B, A8,Cleaned_Data!G:G,"Withdrawal") -> 111794 | D8: =B8 - C8 -> -5894
A9: August | B9: =SUMIFS(Cleaned_Data!F:F,Cleaned_Data!B:B, A9,Cleaned_Data!G:G,"Deposit") -> 587483 | C9: =SUMIFS(Cleaned_Data!E:E,Cleaned_Data!B:B, A9,Cleaned_Data!G:G,"Withdrawal") -> 583402 | D9: =B9 - C9 -> 4081
A10: September | B10: =SUMIFS(Cleaned_Data!F:F,Cleaned_Data!B:B, A10,Cleaned_Data!G:G,"Deposit") -> 242371.5 | C10: =SUMIFS(Cleaned_Data!E:E,Cleaned_Data!B:B, A10,Cleaned_Data!G:G,"Withdrawal") -> 230945 | D10: =B10 - C10 -> 11426.5
A11: October | B11: =SUMIFS(Cleaned_Data!F:F,Cleaned_Data!B:B, A11,Cleaned_Data!G:G,"Deposit") -> 155850 | C11: =SUMIFS(Cleaned_Data!E:E,Cleaned_Data!B:B, A11,Cleaned_Data!G:G,"Withdrawal") -> 164052.65 | D11: =B11 - C11 -> -8202.65
A12: November | B12: =SUMIFS(Cleaned_Data!F:F,Cleaned_Data!B:B, A12,Cleaned_Data!G:G,"Deposit") -> 199502.62 | C12: =SUMIFS(Cleaned_Data!E:E,Cleaned_Data!B:B, A12,Cleaned_Data!G:G,"Withdrawal") -> 206950 | D12: =B12 - C12 -> -7447.38
A13: December | B13: =SUMIFS(Cleaned_Data!F:F,Cleaned_Data!B:B, A13,Cleaned_Data!G:G,"Deposit") -> 182529 | C13: =SUMIFS(Cleaned_Data!E:E,Cleaned_Data!B:B, A13,Cleaned_Data!G:G,"Withdrawal") -> 176248 | D13: =B13 - C13 -> 6281

Sheet Sheet4
A1: Personal Finance Analysis Transaction Charts
